2022-05-19 19:31:23 [ERROR   ] (exception.response_for_exception) Invalid HTTP_HOST header: '0.0.0.0:8000'. You may need to add '0.0.0.0' to ALLOWED_HOSTS.
2022-05-19 19:31:23 [ERROR   ] (exception.response_for_exception) Invalid HTTP_HOST header: '0.0.0.0:8000'. You may need to add '0.0.0.0' to ALLOWED_HOSTS.
2022-05-19 19:31:25 [ERROR   ] (exception.response_for_exception) Invalid HTTP_HOST header: '0.0.0.0:8000'. You may need to add '0.0.0.0' to ALLOWED_HOSTS.
2022-05-19 19:31:25 [ERROR   ] (exception.response_for_exception) Invalid HTTP_HOST header: '0.0.0.0:8000'. You may need to add '0.0.0.0' to ALLOWED_HOSTS.
2022-05-19 19:31:34 [ERROR   ] (log.log_response) Internal Server Error: /
Traceback (most recent call last):
  File "/usr/local/lib/python3.8/site-packages/django/db/backends/utils.py", line 89, in _execute
    return self.cursor.execute(sql, params)
  File "/usr/local/lib/python3.8/site-packages/django/db/backends/mysql/base.py", line 75, in execute
    return self.cursor.execute(query, args)
  File "/usr/local/lib/python3.8/site-packages/MySQLdb/cursors.py", line 206, in execute
    res = self._query(query)
  File "/usr/local/lib/python3.8/site-packages/MySQLdb/cursors.py", line 319, in _query
    db.query(q)
  File "/usr/local/lib/python3.8/site-packages/MySQLdb/connections.py", line 254, in query
    _mysql.connection.query(self, query)
MySQLdb._exceptions.ProgrammingError: (1146, "Table 'db_django.women_women' doesn't exist")

The above exception was the direct cause of the following exception:

Traceback (most recent call last):
  File "/usr/local/lib/python3.8/site-packages/django/core/handlers/exception.py", line 55, in inner
    response = get_response(request)
  File "/usr/local/lib/python3.8/site-packages/django/core/handlers/base.py", line 197, in _get_response
    response = wrapped_callback(request, *callback_args, **callback_kwargs)
  File "/usr/local/lib/python3.8/site-packages/django/views/generic/base.py", line 84, in view
    return self.dispatch(request, *args, **kwargs)
  File "/usr/local/lib/python3.8/site-packages/django/views/generic/base.py", line 119, in dispatch
    return handler(request, *args, **kwargs)
  File "/usr/local/lib/python3.8/site-packages/django/views/generic/list.py", line 174, in get
    context = self.get_context_data()
  File "/web_django/women/views.py", line 22, in get_context_data
    context = super().get_context_data(**kwargs)
  File "/usr/local/lib/python3.8/site-packages/django/views/generic/list.py", line 128, in get_context_data
    paginator, page, queryset, is_paginated = self.paginate_queryset(
  File "/usr/local/lib/python3.8/site-packages/django/views/generic/list.py", line 73, in paginate_queryset
    page = paginator.page(page_number)
  File "/usr/local/lib/python3.8/site-packages/django/core/paginator.py", line 75, in page
    number = self.validate_number(number)
  File "/usr/local/lib/python3.8/site-packages/django/core/paginator.py", line 53, in validate_number
    if number > self.num_pages:
  File "/usr/local/lib/python3.8/site-packages/django/utils/functional.py", line 49, in __get__
    res = instance.__dict__[self.name] = self.func(instance)
  File "/usr/local/lib/python3.8/site-packages/django/core/paginator.py", line 102, in num_pages
    if self.count == 0 and not self.allow_empty_first_page:
  File "/usr/local/lib/python3.8/site-packages/django/utils/functional.py", line 49, in __get__
    res = instance.__dict__[self.name] = self.func(instance)
  File "/usr/local/lib/python3.8/site-packages/django/core/paginator.py", line 96, in count
    return c()
  File "/usr/local/lib/python3.8/site-packages/django/db/models/query.py", line 470, in count
    return self.query.get_count(using=self.db)
  File "/usr/local/lib/python3.8/site-packages/django/db/models/sql/query.py", line 552, in get_count
    number = obj.get_aggregation(using, ["__count"])["__count"]
  File "/usr/local/lib/python3.8/site-packages/django/db/models/sql/query.py", line 537, in get_aggregation
    result = compiler.execute_sql(SINGLE)
  File "/usr/local/lib/python3.8/site-packages/django/db/models/sql/compiler.py", line 1361, in execute_sql
    cursor.execute(sql, params)
  File "/usr/local/lib/python3.8/site-packages/django/db/backends/utils.py", line 103, in execute
    return super().execute(sql, params)
  File "/usr/local/lib/python3.8/site-packages/django/db/backends/utils.py", line 67, in execute
    return self._execute_with_wrappers(
  File "/usr/local/lib/python3.8/site-packages/django/db/backends/utils.py", line 80, in _execute_with_wrappers
    return executor(sql, params, many, context)
  File "/usr/local/lib/python3.8/site-packages/django/db/backends/utils.py", line 89, in _execute
    return self.cursor.execute(sql, params)
  File "/usr/local/lib/python3.8/site-packages/django/db/utils.py", line 91, in __exit__
    raise dj_exc_value.with_traceback(traceback) from exc_value
  File "/usr/local/lib/python3.8/site-packages/django/db/backends/utils.py", line 89, in _execute
    return self.cursor.execute(sql, params)
  File "/usr/local/lib/python3.8/site-packages/django/db/backends/mysql/base.py", line 75, in execute
    return self.cursor.execute(query, args)
  File "/usr/local/lib/python3.8/site-packages/MySQLdb/cursors.py", line 206, in execute
    res = self._query(query)
  File "/usr/local/lib/python3.8/site-packages/MySQLdb/cursors.py", line 319, in _query
    db.query(q)
  File "/usr/local/lib/python3.8/site-packages/MySQLdb/connections.py", line 254, in query
    _mysql.connection.query(self, query)
django.db.utils.ProgrammingError: (1146, "Table 'db_django.women_women' doesn't exist")
2022-05-19 19:31:34 [ERROR   ] (log.log_response) Internal Server Error: /
Traceback (most recent call last):
  File "/usr/local/lib/python3.8/site-packages/django/db/backends/utils.py", line 89, in _execute
    return self.cursor.execute(sql, params)
  File "/usr/local/lib/python3.8/site-packages/django/db/backends/mysql/base.py", line 75, in execute
    return self.cursor.execute(query, args)
  File "/usr/local/lib/python3.8/site-packages/MySQLdb/cursors.py", line 206, in execute
    res = self._query(query)
  File "/usr/local/lib/python3.8/site-packages/MySQLdb/cursors.py", line 319, in _query
    db.query(q)
  File "/usr/local/lib/python3.8/site-packages/MySQLdb/connections.py", line 254, in query
    _mysql.connection.query(self, query)
MySQLdb._exceptions.ProgrammingError: (1146, "Table 'db_django.women_women' doesn't exist")

The above exception was the direct cause of the following exception:

Traceback (most recent call last):
  File "/usr/local/lib/python3.8/site-packages/django/core/handlers/exception.py", line 55, in inner
    response = get_response(request)
  File "/usr/local/lib/python3.8/site-packages/django/core/handlers/base.py", line 197, in _get_response
    response = wrapped_callback(request, *callback_args, **callback_kwargs)
  File "/usr/local/lib/python3.8/site-packages/django/views/generic/base.py", line 84, in view
    return self.dispatch(request, *args, **kwargs)
  File "/usr/local/lib/python3.8/site-packages/django/views/generic/base.py", line 119, in dispatch
    return handler(request, *args, **kwargs)
  File "/usr/local/lib/python3.8/site-packages/django/views/generic/list.py", line 174, in get
    context = self.get_context_data()
  File "/web_django/women/views.py", line 22, in get_context_data
    context = super().get_context_data(**kwargs)
  File "/usr/local/lib/python3.8/site-packages/django/views/generic/list.py", line 128, in get_context_data
    paginator, page, queryset, is_paginated = self.paginate_queryset(
  File "/usr/local/lib/python3.8/site-packages/django/views/generic/list.py", line 73, in paginate_queryset
    page = paginator.page(page_number)
  File "/usr/local/lib/python3.8/site-packages/django/core/paginator.py", line 75, in page
    number = self.validate_number(number)
  File "/usr/local/lib/python3.8/site-packages/django/core/paginator.py", line 53, in validate_number
    if number > self.num_pages:
  File "/usr/local/lib/python3.8/site-packages/django/utils/functional.py", line 49, in __get__
    res = instance.__dict__[self.name] = self.func(instance)
  File "/usr/local/lib/python3.8/site-packages/django/core/paginator.py", line 102, in num_pages
    if self.count == 0 and not self.allow_empty_first_page:
  File "/usr/local/lib/python3.8/site-packages/django/utils/functional.py", line 49, in __get__
    res = instance.__dict__[self.name] = self.func(instance)
  File "/usr/local/lib/python3.8/site-packages/django/core/paginator.py", line 96, in count
    return c()
  File "/usr/local/lib/python3.8/site-packages/django/db/models/query.py", line 470, in count
    return self.query.get_count(using=self.db)
  File "/usr/local/lib/python3.8/site-packages/django/db/models/sql/query.py", line 552, in get_count
    number = obj.get_aggregation(using, ["__count"])["__count"]
  File "/usr/local/lib/python3.8/site-packages/django/db/models/sql/query.py", line 537, in get_aggregation
    result = compiler.execute_sql(SINGLE)
  File "/usr/local/lib/python3.8/site-packages/django/db/models/sql/compiler.py", line 1361, in execute_sql
    cursor.execute(sql, params)
  File "/usr/local/lib/python3.8/site-packages/django/db/backends/utils.py", line 103, in execute
    return super().execute(sql, params)
  File "/usr/local/lib/python3.8/site-packages/django/db/backends/utils.py", line 67, in execute
    return self._execute_with_wrappers(
  File "/usr/local/lib/python3.8/site-packages/django/db/backends/utils.py", line 80, in _execute_with_wrappers
    return executor(sql, params, many, context)
  File "/usr/local/lib/python3.8/site-packages/django/db/backends/utils.py", line 89, in _execute
    return self.cursor.execute(sql, params)
  File "/usr/local/lib/python3.8/site-packages/django/db/utils.py", line 91, in __exit__
    raise dj_exc_value.with_traceback(traceback) from exc_value
  File "/usr/local/lib/python3.8/site-packages/django/db/backends/utils.py", line 89, in _execute
    return self.cursor.execute(sql, params)
  File "/usr/local/lib/python3.8/site-packages/django/db/backends/mysql/base.py", line 75, in execute
    return self.cursor.execute(query, args)
  File "/usr/local/lib/python3.8/site-packages/MySQLdb/cursors.py", line 206, in execute
    res = self._query(query)
  File "/usr/local/lib/python3.8/site-packages/MySQLdb/cursors.py", line 319, in _query
    db.query(q)
  File "/usr/local/lib/python3.8/site-packages/MySQLdb/connections.py", line 254, in query
    _mysql.connection.query(self, query)
django.db.utils.ProgrammingError: (1146, "Table 'db_django.women_women' doesn't exist")
2022-05-19 19:31:34 [ERROR   ] (basehttp.log_message) "GET / HTTP/1.1" 500 187070
2022-05-19 19:31:34 [ERROR   ] (basehttp.log_message) "GET / HTTP/1.1" 500 187070
2022-05-19 20:19:14 [ERROR   ] (log.log_response) Internal Server Error: /
Traceback (most recent call last):
  File "/usr/local/lib/python3.8/site-packages/django/db/backends/utils.py", line 89, in _execute
    return self.cursor.execute(sql, params)
psycopg2.errors.UndefinedTable: relation "women_women" does not exist
LINE 1: SELECT COUNT(*) AS "__count" FROM "women_women" WHERE "women...
                                          ^


The above exception was the direct cause of the following exception:

Traceback (most recent call last):
  File "/usr/local/lib/python3.8/site-packages/django/core/handlers/exception.py", line 55, in inner
    response = get_response(request)
  File "/usr/local/lib/python3.8/site-packages/django/core/handlers/base.py", line 197, in _get_response
    response = wrapped_callback(request, *callback_args, **callback_kwargs)
  File "/usr/local/lib/python3.8/site-packages/django/views/generic/base.py", line 84, in view
    return self.dispatch(request, *args, **kwargs)
  File "/usr/local/lib/python3.8/site-packages/django/views/generic/base.py", line 119, in dispatch
    return handler(request, *args, **kwargs)
  File "/usr/local/lib/python3.8/site-packages/django/views/generic/list.py", line 174, in get
    context = self.get_context_data()
  File "/web_django/women/views.py", line 22, in get_context_data
    context = super().get_context_data(**kwargs)
  File "/usr/local/lib/python3.8/site-packages/django/views/generic/list.py", line 128, in get_context_data
    paginator, page, queryset, is_paginated = self.paginate_queryset(
  File "/usr/local/lib/python3.8/site-packages/django/views/generic/list.py", line 73, in paginate_queryset
    page = paginator.page(page_number)
  File "/usr/local/lib/python3.8/site-packages/django/core/paginator.py", line 75, in page
    number = self.validate_number(number)
  File "/usr/local/lib/python3.8/site-packages/django/core/paginator.py", line 53, in validate_number
    if number > self.num_pages:
  File "/usr/local/lib/python3.8/site-packages/django/utils/functional.py", line 49, in __get__
    res = instance.__dict__[self.name] = self.func(instance)
  File "/usr/local/lib/python3.8/site-packages/django/core/paginator.py", line 102, in num_pages
    if self.count == 0 and not self.allow_empty_first_page:
  File "/usr/local/lib/python3.8/site-packages/django/utils/functional.py", line 49, in __get__
    res = instance.__dict__[self.name] = self.func(instance)
  File "/usr/local/lib/python3.8/site-packages/django/core/paginator.py", line 96, in count
    return c()
  File "/usr/local/lib/python3.8/site-packages/django/db/models/query.py", line 470, in count
    return self.query.get_count(using=self.db)
  File "/usr/local/lib/python3.8/site-packages/django/db/models/sql/query.py", line 552, in get_count
    number = obj.get_aggregation(using, ["__count"])["__count"]
  File "/usr/local/lib/python3.8/site-packages/django/db/models/sql/query.py", line 537, in get_aggregation
    result = compiler.execute_sql(SINGLE)
  File "/usr/local/lib/python3.8/site-packages/django/db/models/sql/compiler.py", line 1361, in execute_sql
    cursor.execute(sql, params)
  File "/usr/local/lib/python3.8/site-packages/django/db/backends/utils.py", line 103, in execute
    return super().execute(sql, params)
  File "/usr/local/lib/python3.8/site-packages/django/db/backends/utils.py", line 67, in execute
    return self._execute_with_wrappers(
  File "/usr/local/lib/python3.8/site-packages/django/db/backends/utils.py", line 80, in _execute_with_wrappers
    return executor(sql, params, many, context)
  File "/usr/local/lib/python3.8/site-packages/django/db/backends/utils.py", line 89, in _execute
    return self.cursor.execute(sql, params)
  File "/usr/local/lib/python3.8/site-packages/django/db/utils.py", line 91, in __exit__
    raise dj_exc_value.with_traceback(traceback) from exc_value
  File "/usr/local/lib/python3.8/site-packages/django/db/backends/utils.py", line 89, in _execute
    return self.cursor.execute(sql, params)
django.db.utils.ProgrammingError: relation "women_women" does not exist
LINE 1: SELECT COUNT(*) AS "__count" FROM "women_women" WHERE "women...
                                          ^

2022-05-19 20:19:14 [ERROR   ] (log.log_response) Internal Server Error: /
Traceback (most recent call last):
  File "/usr/local/lib/python3.8/site-packages/django/db/backends/utils.py", line 89, in _execute
    return self.cursor.execute(sql, params)
psycopg2.errors.UndefinedTable: relation "women_women" does not exist
LINE 1: SELECT COUNT(*) AS "__count" FROM "women_women" WHERE "women...
                                          ^


The above exception was the direct cause of the following exception:

Traceback (most recent call last):
  File "/usr/local/lib/python3.8/site-packages/django/core/handlers/exception.py", line 55, in inner
    response = get_response(request)
  File "/usr/local/lib/python3.8/site-packages/django/core/handlers/base.py", line 197, in _get_response
    response = wrapped_callback(request, *callback_args, **callback_kwargs)
  File "/usr/local/lib/python3.8/site-packages/django/views/generic/base.py", line 84, in view
    return self.dispatch(request, *args, **kwargs)
  File "/usr/local/lib/python3.8/site-packages/django/views/generic/base.py", line 119, in dispatch
    return handler(request, *args, **kwargs)
  File "/usr/local/lib/python3.8/site-packages/django/views/generic/list.py", line 174, in get
    context = self.get_context_data()
  File "/web_django/women/views.py", line 22, in get_context_data
    context = super().get_context_data(**kwargs)
  File "/usr/local/lib/python3.8/site-packages/django/views/generic/list.py", line 128, in get_context_data
    paginator, page, queryset, is_paginated = self.paginate_queryset(
  File "/usr/local/lib/python3.8/site-packages/django/views/generic/list.py", line 73, in paginate_queryset
    page = paginator.page(page_number)
  File "/usr/local/lib/python3.8/site-packages/django/core/paginator.py", line 75, in page
    number = self.validate_number(number)
  File "/usr/local/lib/python3.8/site-packages/django/core/paginator.py", line 53, in validate_number
    if number > self.num_pages:
  File "/usr/local/lib/python3.8/site-packages/django/utils/functional.py", line 49, in __get__
    res = instance.__dict__[self.name] = self.func(instance)
  File "/usr/local/lib/python3.8/site-packages/django/core/paginator.py", line 102, in num_pages
    if self.count == 0 and not self.allow_empty_first_page:
  File "/usr/local/lib/python3.8/site-packages/django/utils/functional.py", line 49, in __get__
    res = instance.__dict__[self.name] = self.func(instance)
  File "/usr/local/lib/python3.8/site-packages/django/core/paginator.py", line 96, in count
    return c()
  File "/usr/local/lib/python3.8/site-packages/django/db/models/query.py", line 470, in count
    return self.query.get_count(using=self.db)
  File "/usr/local/lib/python3.8/site-packages/django/db/models/sql/query.py", line 552, in get_count
    number = obj.get_aggregation(using, ["__count"])["__count"]
  File "/usr/local/lib/python3.8/site-packages/django/db/models/sql/query.py", line 537, in get_aggregation
    result = compiler.execute_sql(SINGLE)
  File "/usr/local/lib/python3.8/site-packages/django/db/models/sql/compiler.py", line 1361, in execute_sql
    cursor.execute(sql, params)
  File "/usr/local/lib/python3.8/site-packages/django/db/backends/utils.py", line 103, in execute
    return super().execute(sql, params)
  File "/usr/local/lib/python3.8/site-packages/django/db/backends/utils.py", line 67, in execute
    return self._execute_with_wrappers(
  File "/usr/local/lib/python3.8/site-packages/django/db/backends/utils.py", line 80, in _execute_with_wrappers
    return executor(sql, params, many, context)
  File "/usr/local/lib/python3.8/site-packages/django/db/backends/utils.py", line 89, in _execute
    return self.cursor.execute(sql, params)
  File "/usr/local/lib/python3.8/site-packages/django/db/utils.py", line 91, in __exit__
    raise dj_exc_value.with_traceback(traceback) from exc_value
  File "/usr/local/lib/python3.8/site-packages/django/db/backends/utils.py", line 89, in _execute
    return self.cursor.execute(sql, params)
django.db.utils.ProgrammingError: relation "women_women" does not exist
LINE 1: SELECT COUNT(*) AS "__count" FROM "women_women" WHERE "women...
                                          ^

2022-05-19 20:19:14 [ERROR   ] (basehttp.log_message) "GET / HTTP/1.1" 500 156997
2022-05-19 20:19:14 [ERROR   ] (basehttp.log_message) "GET / HTTP/1.1" 500 156997
2022-05-20 06:19:47 [ERROR   ] (log.log_response) Internal Server Error: /
Traceback (most recent call last):
  File "/usr/local/lib/python3.8/site-packages/django/db/backends/utils.py", line 89, in _execute
    return self.cursor.execute(sql, params)
psycopg2.errors.UndefinedTable: relation "women_women" does not exist
LINE 1: SELECT COUNT(*) AS "__count" FROM "women_women" WHERE "women...
                                          ^


The above exception was the direct cause of the following exception:

Traceback (most recent call last):
  File "/usr/local/lib/python3.8/site-packages/django/core/handlers/exception.py", line 55, in inner
    response = get_response(request)
  File "/usr/local/lib/python3.8/site-packages/django/core/handlers/base.py", line 197, in _get_response
    response = wrapped_callback(request, *callback_args, **callback_kwargs)
  File "/usr/local/lib/python3.8/site-packages/django/views/generic/base.py", line 84, in view
    return self.dispatch(request, *args, **kwargs)
  File "/usr/local/lib/python3.8/site-packages/django/views/generic/base.py", line 119, in dispatch
    return handler(request, *args, **kwargs)
  File "/usr/local/lib/python3.8/site-packages/django/views/generic/list.py", line 174, in get
    context = self.get_context_data()
  File "/web_django/women/views.py", line 22, in get_context_data
    context = super().get_context_data(**kwargs)
  File "/usr/local/lib/python3.8/site-packages/django/views/generic/list.py", line 128, in get_context_data
    paginator, page, queryset, is_paginated = self.paginate_queryset(
  File "/usr/local/lib/python3.8/site-packages/django/views/generic/list.py", line 73, in paginate_queryset
    page = paginator.page(page_number)
  File "/usr/local/lib/python3.8/site-packages/django/core/paginator.py", line 75, in page
    number = self.validate_number(number)
  File "/usr/local/lib/python3.8/site-packages/django/core/paginator.py", line 53, in validate_number
    if number > self.num_pages:
  File "/usr/local/lib/python3.8/site-packages/django/utils/functional.py", line 49, in __get__
    res = instance.__dict__[self.name] = self.func(instance)
  File "/usr/local/lib/python3.8/site-packages/django/core/paginator.py", line 102, in num_pages
    if self.count == 0 and not self.allow_empty_first_page:
  File "/usr/local/lib/python3.8/site-packages/django/utils/functional.py", line 49, in __get__
    res = instance.__dict__[self.name] = self.func(instance)
  File "/usr/local/lib/python3.8/site-packages/django/core/paginator.py", line 96, in count
    return c()
  File "/usr/local/lib/python3.8/site-packages/django/db/models/query.py", line 470, in count
    return self.query.get_count(using=self.db)
  File "/usr/local/lib/python3.8/site-packages/django/db/models/sql/query.py", line 552, in get_count
    number = obj.get_aggregation(using, ["__count"])["__count"]
  File "/usr/local/lib/python3.8/site-packages/django/db/models/sql/query.py", line 537, in get_aggregation
    result = compiler.execute_sql(SINGLE)
  File "/usr/local/lib/python3.8/site-packages/django/db/models/sql/compiler.py", line 1361, in execute_sql
    cursor.execute(sql, params)
  File "/usr/local/lib/python3.8/site-packages/django/db/backends/utils.py", line 103, in execute
    return super().execute(sql, params)
  File "/usr/local/lib/python3.8/site-packages/django/db/backends/utils.py", line 67, in execute
    return self._execute_with_wrappers(
  File "/usr/local/lib/python3.8/site-packages/django/db/backends/utils.py", line 80, in _execute_with_wrappers
    return executor(sql, params, many, context)
  File "/usr/local/lib/python3.8/site-packages/django/db/backends/utils.py", line 89, in _execute
    return self.cursor.execute(sql, params)
  File "/usr/local/lib/python3.8/site-packages/django/db/utils.py", line 91, in __exit__
    raise dj_exc_value.with_traceback(traceback) from exc_value
  File "/usr/local/lib/python3.8/site-packages/django/db/backends/utils.py", line 89, in _execute
    return self.cursor.execute(sql, params)
django.db.utils.ProgrammingError: relation "women_women" does not exist
LINE 1: SELECT COUNT(*) AS "__count" FROM "women_women" WHERE "women...
                                          ^

2022-05-20 06:19:47 [ERROR   ] (log.log_response) Internal Server Error: /
Traceback (most recent call last):
  File "/usr/local/lib/python3.8/site-packages/django/db/backends/utils.py", line 89, in _execute
    return self.cursor.execute(sql, params)
psycopg2.errors.UndefinedTable: relation "women_women" does not exist
LINE 1: SELECT COUNT(*) AS "__count" FROM "women_women" WHERE "women...
                                          ^


The above exception was the direct cause of the following exception:

Traceback (most recent call last):
  File "/usr/local/lib/python3.8/site-packages/django/core/handlers/exception.py", line 55, in inner
    response = get_response(request)
  File "/usr/local/lib/python3.8/site-packages/django/core/handlers/base.py", line 197, in _get_response
    response = wrapped_callback(request, *callback_args, **callback_kwargs)
  File "/usr/local/lib/python3.8/site-packages/django/views/generic/base.py", line 84, in view
    return self.dispatch(request, *args, **kwargs)
  File "/usr/local/lib/python3.8/site-packages/django/views/generic/base.py", line 119, in dispatch
    return handler(request, *args, **kwargs)
  File "/usr/local/lib/python3.8/site-packages/django/views/generic/list.py", line 174, in get
    context = self.get_context_data()
  File "/web_django/women/views.py", line 22, in get_context_data
    context = super().get_context_data(**kwargs)
  File "/usr/local/lib/python3.8/site-packages/django/views/generic/list.py", line 128, in get_context_data
    paginator, page, queryset, is_paginated = self.paginate_queryset(
  File "/usr/local/lib/python3.8/site-packages/django/views/generic/list.py", line 73, in paginate_queryset
    page = paginator.page(page_number)
  File "/usr/local/lib/python3.8/site-packages/django/core/paginator.py", line 75, in page
    number = self.validate_number(number)
  File "/usr/local/lib/python3.8/site-packages/django/core/paginator.py", line 53, in validate_number
    if number > self.num_pages:
  File "/usr/local/lib/python3.8/site-packages/django/utils/functional.py", line 49, in __get__
    res = instance.__dict__[self.name] = self.func(instance)
  File "/usr/local/lib/python3.8/site-packages/django/core/paginator.py", line 102, in num_pages
    if self.count == 0 and not self.allow_empty_first_page:
  File "/usr/local/lib/python3.8/site-packages/django/utils/functional.py", line 49, in __get__
    res = instance.__dict__[self.name] = self.func(instance)
  File "/usr/local/lib/python3.8/site-packages/django/core/paginator.py", line 96, in count
    return c()
  File "/usr/local/lib/python3.8/site-packages/django/db/models/query.py", line 470, in count
    return self.query.get_count(using=self.db)
  File "/usr/local/lib/python3.8/site-packages/django/db/models/sql/query.py", line 552, in get_count
    number = obj.get_aggregation(using, ["__count"])["__count"]
  File "/usr/local/lib/python3.8/site-packages/django/db/models/sql/query.py", line 537, in get_aggregation
    result = compiler.execute_sql(SINGLE)
  File "/usr/local/lib/python3.8/site-packages/django/db/models/sql/compiler.py", line 1361, in execute_sql
    cursor.execute(sql, params)
  File "/usr/local/lib/python3.8/site-packages/django/db/backends/utils.py", line 103, in execute
    return super().execute(sql, params)
  File "/usr/local/lib/python3.8/site-packages/django/db/backends/utils.py", line 67, in execute
    return self._execute_with_wrappers(
  File "/usr/local/lib/python3.8/site-packages/django/db/backends/utils.py", line 80, in _execute_with_wrappers
    return executor(sql, params, many, context)
  File "/usr/local/lib/python3.8/site-packages/django/db/backends/utils.py", line 89, in _execute
    return self.cursor.execute(sql, params)
  File "/usr/local/lib/python3.8/site-packages/django/db/utils.py", line 91, in __exit__
    raise dj_exc_value.with_traceback(traceback) from exc_value
  File "/usr/local/lib/python3.8/site-packages/django/db/backends/utils.py", line 89, in _execute
    return self.cursor.execute(sql, params)
django.db.utils.ProgrammingError: relation "women_women" does not exist
LINE 1: SELECT COUNT(*) AS "__count" FROM "women_women" WHERE "women...
                                          ^

2022-05-20 06:19:47 [ERROR   ] (basehttp.log_message) "GET / HTTP/1.1" 500 156997
2022-05-20 06:19:47 [ERROR   ] (basehttp.log_message) "GET / HTTP/1.1" 500 156997
2022-05-20 06:19:49 [ERROR   ] (log.log_response) Internal Server Error: /
Traceback (most recent call last):
  File "/usr/local/lib/python3.8/site-packages/django/db/backends/utils.py", line 89, in _execute
    return self.cursor.execute(sql, params)
psycopg2.errors.UndefinedTable: relation "women_women" does not exist
LINE 1: SELECT COUNT(*) AS "__count" FROM "women_women" WHERE "women...
                                          ^


The above exception was the direct cause of the following exception:

Traceback (most recent call last):
  File "/usr/local/lib/python3.8/site-packages/django/core/handlers/exception.py", line 55, in inner
    response = get_response(request)
  File "/usr/local/lib/python3.8/site-packages/django/core/handlers/base.py", line 197, in _get_response
    response = wrapped_callback(request, *callback_args, **callback_kwargs)
  File "/usr/local/lib/python3.8/site-packages/django/views/generic/base.py", line 84, in view
    return self.dispatch(request, *args, **kwargs)
  File "/usr/local/lib/python3.8/site-packages/django/views/generic/base.py", line 119, in dispatch
    return handler(request, *args, **kwargs)
  File "/usr/local/lib/python3.8/site-packages/django/views/generic/list.py", line 174, in get
    context = self.get_context_data()
  File "/web_django/women/views.py", line 22, in get_context_data
    context = super().get_context_data(**kwargs)
  File "/usr/local/lib/python3.8/site-packages/django/views/generic/list.py", line 128, in get_context_data
    paginator, page, queryset, is_paginated = self.paginate_queryset(
  File "/usr/local/lib/python3.8/site-packages/django/views/generic/list.py", line 73, in paginate_queryset
    page = paginator.page(page_number)
  File "/usr/local/lib/python3.8/site-packages/django/core/paginator.py", line 75, in page
    number = self.validate_number(number)
  File "/usr/local/lib/python3.8/site-packages/django/core/paginator.py", line 53, in validate_number
    if number > self.num_pages:
  File "/usr/local/lib/python3.8/site-packages/django/utils/functional.py", line 49, in __get__
    res = instance.__dict__[self.name] = self.func(instance)
  File "/usr/local/lib/python3.8/site-packages/django/core/paginator.py", line 102, in num_pages
    if self.count == 0 and not self.allow_empty_first_page:
  File "/usr/local/lib/python3.8/site-packages/django/utils/functional.py", line 49, in __get__
    res = instance.__dict__[self.name] = self.func(instance)
  File "/usr/local/lib/python3.8/site-packages/django/core/paginator.py", line 96, in count
    return c()
  File "/usr/local/lib/python3.8/site-packages/django/db/models/query.py", line 470, in count
    return self.query.get_count(using=self.db)
  File "/usr/local/lib/python3.8/site-packages/django/db/models/sql/query.py", line 552, in get_count
    number = obj.get_aggregation(using, ["__count"])["__count"]
  File "/usr/local/lib/python3.8/site-packages/django/db/models/sql/query.py", line 537, in get_aggregation
    result = compiler.execute_sql(SINGLE)
  File "/usr/local/lib/python3.8/site-packages/django/db/models/sql/compiler.py", line 1361, in execute_sql
    cursor.execute(sql, params)
  File "/usr/local/lib/python3.8/site-packages/django/db/backends/utils.py", line 103, in execute
    return super().execute(sql, params)
  File "/usr/local/lib/python3.8/site-packages/django/db/backends/utils.py", line 67, in execute
    return self._execute_with_wrappers(
  File "/usr/local/lib/python3.8/site-packages/django/db/backends/utils.py", line 80, in _execute_with_wrappers
    return executor(sql, params, many, context)
  File "/usr/local/lib/python3.8/site-packages/django/db/backends/utils.py", line 89, in _execute
    return self.cursor.execute(sql, params)
  File "/usr/local/lib/python3.8/site-packages/django/db/utils.py", line 91, in __exit__
    raise dj_exc_value.with_traceback(traceback) from exc_value
  File "/usr/local/lib/python3.8/site-packages/django/db/backends/utils.py", line 89, in _execute
    return self.cursor.execute(sql, params)
django.db.utils.ProgrammingError: relation "women_women" does not exist
LINE 1: SELECT COUNT(*) AS "__count" FROM "women_women" WHERE "women...
                                          ^

2022-05-20 06:19:49 [ERROR   ] (log.log_response) Internal Server Error: /
Traceback (most recent call last):
  File "/usr/local/lib/python3.8/site-packages/django/db/backends/utils.py", line 89, in _execute
    return self.cursor.execute(sql, params)
psycopg2.errors.UndefinedTable: relation "women_women" does not exist
LINE 1: SELECT COUNT(*) AS "__count" FROM "women_women" WHERE "women...
                                          ^


The above exception was the direct cause of the following exception:

Traceback (most recent call last):
  File "/usr/local/lib/python3.8/site-packages/django/core/handlers/exception.py", line 55, in inner
    response = get_response(request)
  File "/usr/local/lib/python3.8/site-packages/django/core/handlers/base.py", line 197, in _get_response
    response = wrapped_callback(request, *callback_args, **callback_kwargs)
  File "/usr/local/lib/python3.8/site-packages/django/views/generic/base.py", line 84, in view
    return self.dispatch(request, *args, **kwargs)
  File "/usr/local/lib/python3.8/site-packages/django/views/generic/base.py", line 119, in dispatch
    return handler(request, *args, **kwargs)
  File "/usr/local/lib/python3.8/site-packages/django/views/generic/list.py", line 174, in get
    context = self.get_context_data()
  File "/web_django/women/views.py", line 22, in get_context_data
    context = super().get_context_data(**kwargs)
  File "/usr/local/lib/python3.8/site-packages/django/views/generic/list.py", line 128, in get_context_data
    paginator, page, queryset, is_paginated = self.paginate_queryset(
  File "/usr/local/lib/python3.8/site-packages/django/views/generic/list.py", line 73, in paginate_queryset
    page = paginator.page(page_number)
  File "/usr/local/lib/python3.8/site-packages/django/core/paginator.py", line 75, in page
    number = self.validate_number(number)
  File "/usr/local/lib/python3.8/site-packages/django/core/paginator.py", line 53, in validate_number
    if number > self.num_pages:
  File "/usr/local/lib/python3.8/site-packages/django/utils/functional.py", line 49, in __get__
    res = instance.__dict__[self.name] = self.func(instance)
  File "/usr/local/lib/python3.8/site-packages/django/core/paginator.py", line 102, in num_pages
    if self.count == 0 and not self.allow_empty_first_page:
  File "/usr/local/lib/python3.8/site-packages/django/utils/functional.py", line 49, in __get__
    res = instance.__dict__[self.name] = self.func(instance)
  File "/usr/local/lib/python3.8/site-packages/django/core/paginator.py", line 96, in count
    return c()
  File "/usr/local/lib/python3.8/site-packages/django/db/models/query.py", line 470, in count
    return self.query.get_count(using=self.db)
  File "/usr/local/lib/python3.8/site-packages/django/db/models/sql/query.py", line 552, in get_count
    number = obj.get_aggregation(using, ["__count"])["__count"]
  File "/usr/local/lib/python3.8/site-packages/django/db/models/sql/query.py", line 537, in get_aggregation
    result = compiler.execute_sql(SINGLE)
  File "/usr/local/lib/python3.8/site-packages/django/db/models/sql/compiler.py", line 1361, in execute_sql
    cursor.execute(sql, params)
  File "/usr/local/lib/python3.8/site-packages/django/db/backends/utils.py", line 103, in execute
    return super().execute(sql, params)
  File "/usr/local/lib/python3.8/site-packages/django/db/backends/utils.py", line 67, in execute
    return self._execute_with_wrappers(
  File "/usr/local/lib/python3.8/site-packages/django/db/backends/utils.py", line 80, in _execute_with_wrappers
    return executor(sql, params, many, context)
  File "/usr/local/lib/python3.8/site-packages/django/db/backends/utils.py", line 89, in _execute
    return self.cursor.execute(sql, params)
  File "/usr/local/lib/python3.8/site-packages/django/db/utils.py", line 91, in __exit__
    raise dj_exc_value.with_traceback(traceback) from exc_value
  File "/usr/local/lib/python3.8/site-packages/django/db/backends/utils.py", line 89, in _execute
    return self.cursor.execute(sql, params)
django.db.utils.ProgrammingError: relation "women_women" does not exist
LINE 1: SELECT COUNT(*) AS "__count" FROM "women_women" WHERE "women...
                                          ^

2022-05-20 06:19:49 [ERROR   ] (basehttp.log_message) "GET / HTTP/1.1" 500 156997
2022-05-20 06:19:49 [ERROR   ] (basehttp.log_message) "GET / HTTP/1.1" 500 156997
2022-05-20 06:29:49 [ERROR   ] (log.log_response) Internal Server Error: /
Traceback (most recent call last):
  File "/usr/local/lib/python3.8/site-packages/django/db/backends/utils.py", line 89, in _execute
    return self.cursor.execute(sql, params)
psycopg2.errors.UndefinedTable: relation "women_women" does not exist
LINE 1: SELECT COUNT(*) AS "__count" FROM "women_women" WHERE "women...
                                          ^


The above exception was the direct cause of the following exception:

Traceback (most recent call last):
  File "/usr/local/lib/python3.8/site-packages/django/core/handlers/exception.py", line 55, in inner
    response = get_response(request)
  File "/usr/local/lib/python3.8/site-packages/django/core/handlers/base.py", line 197, in _get_response
    response = wrapped_callback(request, *callback_args, **callback_kwargs)
  File "/usr/local/lib/python3.8/site-packages/django/views/generic/base.py", line 84, in view
    return self.dispatch(request, *args, **kwargs)
  File "/usr/local/lib/python3.8/site-packages/django/views/generic/base.py", line 119, in dispatch
    return handler(request, *args, **kwargs)
  File "/usr/local/lib/python3.8/site-packages/django/views/generic/list.py", line 174, in get
    context = self.get_context_data()
  File "/web_django/women/views.py", line 22, in get_context_data
    context = super().get_context_data(**kwargs)
  File "/usr/local/lib/python3.8/site-packages/django/views/generic/list.py", line 128, in get_context_data
    paginator, page, queryset, is_paginated = self.paginate_queryset(
  File "/usr/local/lib/python3.8/site-packages/django/views/generic/list.py", line 73, in paginate_queryset
    page = paginator.page(page_number)
  File "/usr/local/lib/python3.8/site-packages/django/core/paginator.py", line 75, in page
    number = self.validate_number(number)
  File "/usr/local/lib/python3.8/site-packages/django/core/paginator.py", line 53, in validate_number
    if number > self.num_pages:
  File "/usr/local/lib/python3.8/site-packages/django/utils/functional.py", line 49, in __get__
    res = instance.__dict__[self.name] = self.func(instance)
  File "/usr/local/lib/python3.8/site-packages/django/core/paginator.py", line 102, in num_pages
    if self.count == 0 and not self.allow_empty_first_page:
  File "/usr/local/lib/python3.8/site-packages/django/utils/functional.py", line 49, in __get__
    res = instance.__dict__[self.name] = self.func(instance)
  File "/usr/local/lib/python3.8/site-packages/django/core/paginator.py", line 96, in count
    return c()
  File "/usr/local/lib/python3.8/site-packages/django/db/models/query.py", line 470, in count
    return self.query.get_count(using=self.db)
  File "/usr/local/lib/python3.8/site-packages/django/db/models/sql/query.py", line 552, in get_count
    number = obj.get_aggregation(using, ["__count"])["__count"]
  File "/usr/local/lib/python3.8/site-packages/django/db/models/sql/query.py", line 537, in get_aggregation
    result = compiler.execute_sql(SINGLE)
  File "/usr/local/lib/python3.8/site-packages/django/db/models/sql/compiler.py", line 1361, in execute_sql
    cursor.execute(sql, params)
  File "/usr/local/lib/python3.8/site-packages/django/db/backends/utils.py", line 103, in execute
    return super().execute(sql, params)
  File "/usr/local/lib/python3.8/site-packages/django/db/backends/utils.py", line 67, in execute
    return self._execute_with_wrappers(
  File "/usr/local/lib/python3.8/site-packages/django/db/backends/utils.py", line 80, in _execute_with_wrappers
    return executor(sql, params, many, context)
  File "/usr/local/lib/python3.8/site-packages/django/db/backends/utils.py", line 89, in _execute
    return self.cursor.execute(sql, params)
  File "/usr/local/lib/python3.8/site-packages/django/db/utils.py", line 91, in __exit__
    raise dj_exc_value.with_traceback(traceback) from exc_value
  File "/usr/local/lib/python3.8/site-packages/django/db/backends/utils.py", line 89, in _execute
    return self.cursor.execute(sql, params)
django.db.utils.ProgrammingError: relation "women_women" does not exist
LINE 1: SELECT COUNT(*) AS "__count" FROM "women_women" WHERE "women...
                                          ^

2022-05-20 06:29:49 [ERROR   ] (log.log_response) Internal Server Error: /
Traceback (most recent call last):
  File "/usr/local/lib/python3.8/site-packages/django/db/backends/utils.py", line 89, in _execute
    return self.cursor.execute(sql, params)
psycopg2.errors.UndefinedTable: relation "women_women" does not exist
LINE 1: SELECT COUNT(*) AS "__count" FROM "women_women" WHERE "women...
                                          ^


The above exception was the direct cause of the following exception:

Traceback (most recent call last):
  File "/usr/local/lib/python3.8/site-packages/django/core/handlers/exception.py", line 55, in inner
    response = get_response(request)
  File "/usr/local/lib/python3.8/site-packages/django/core/handlers/base.py", line 197, in _get_response
    response = wrapped_callback(request, *callback_args, **callback_kwargs)
  File "/usr/local/lib/python3.8/site-packages/django/views/generic/base.py", line 84, in view
    return self.dispatch(request, *args, **kwargs)
  File "/usr/local/lib/python3.8/site-packages/django/views/generic/base.py", line 119, in dispatch
    return handler(request, *args, **kwargs)
  File "/usr/local/lib/python3.8/site-packages/django/views/generic/list.py", line 174, in get
    context = self.get_context_data()
  File "/web_django/women/views.py", line 22, in get_context_data
    context = super().get_context_data(**kwargs)
  File "/usr/local/lib/python3.8/site-packages/django/views/generic/list.py", line 128, in get_context_data
    paginator, page, queryset, is_paginated = self.paginate_queryset(
  File "/usr/local/lib/python3.8/site-packages/django/views/generic/list.py", line 73, in paginate_queryset
    page = paginator.page(page_number)
  File "/usr/local/lib/python3.8/site-packages/django/core/paginator.py", line 75, in page
    number = self.validate_number(number)
  File "/usr/local/lib/python3.8/site-packages/django/core/paginator.py", line 53, in validate_number
    if number > self.num_pages:
  File "/usr/local/lib/python3.8/site-packages/django/utils/functional.py", line 49, in __get__
    res = instance.__dict__[self.name] = self.func(instance)
  File "/usr/local/lib/python3.8/site-packages/django/core/paginator.py", line 102, in num_pages
    if self.count == 0 and not self.allow_empty_first_page:
  File "/usr/local/lib/python3.8/site-packages/django/utils/functional.py", line 49, in __get__
    res = instance.__dict__[self.name] = self.func(instance)
  File "/usr/local/lib/python3.8/site-packages/django/core/paginator.py", line 96, in count
    return c()
  File "/usr/local/lib/python3.8/site-packages/django/db/models/query.py", line 470, in count
    return self.query.get_count(using=self.db)
  File "/usr/local/lib/python3.8/site-packages/django/db/models/sql/query.py", line 552, in get_count
    number = obj.get_aggregation(using, ["__count"])["__count"]
  File "/usr/local/lib/python3.8/site-packages/django/db/models/sql/query.py", line 537, in get_aggregation
    result = compiler.execute_sql(SINGLE)
  File "/usr/local/lib/python3.8/site-packages/django/db/models/sql/compiler.py", line 1361, in execute_sql
    cursor.execute(sql, params)
  File "/usr/local/lib/python3.8/site-packages/django/db/backends/utils.py", line 103, in execute
    return super().execute(sql, params)
  File "/usr/local/lib/python3.8/site-packages/django/db/backends/utils.py", line 67, in execute
    return self._execute_with_wrappers(
  File "/usr/local/lib/python3.8/site-packages/django/db/backends/utils.py", line 80, in _execute_with_wrappers
    return executor(sql, params, many, context)
  File "/usr/local/lib/python3.8/site-packages/django/db/backends/utils.py", line 89, in _execute
    return self.cursor.execute(sql, params)
  File "/usr/local/lib/python3.8/site-packages/django/db/utils.py", line 91, in __exit__
    raise dj_exc_value.with_traceback(traceback) from exc_value
  File "/usr/local/lib/python3.8/site-packages/django/db/backends/utils.py", line 89, in _execute
    return self.cursor.execute(sql, params)
django.db.utils.ProgrammingError: relation "women_women" does not exist
LINE 1: SELECT COUNT(*) AS "__count" FROM "women_women" WHERE "women...
                                          ^

2022-05-20 06:29:49 [ERROR   ] (basehttp.log_message) "GET / HTTP/1.1" 500 156860
2022-05-20 06:29:49 [ERROR   ] (basehttp.log_message) "GET / HTTP/1.1" 500 156860
2022-05-23 10:05:35 [ERROR   ] (log.log_response) Internal Server Error: /
Traceback (most recent call last):
  File "/usr/local/lib/python3.8/site-packages/django/db/backends/utils.py", line 89, in _execute
    return self.cursor.execute(sql, params)
psycopg2.errors.UndefinedTable: relation "women_women" does not exist
LINE 1: SELECT COUNT(*) AS "__count" FROM "women_women" WHERE "women...
                                          ^


The above exception was the direct cause of the following exception:

Traceback (most recent call last):
  File "/usr/local/lib/python3.8/site-packages/django/core/handlers/exception.py", line 55, in inner
    response = get_response(request)
  File "/usr/local/lib/python3.8/site-packages/django/core/handlers/base.py", line 197, in _get_response
    response = wrapped_callback(request, *callback_args, **callback_kwargs)
  File "/usr/local/lib/python3.8/site-packages/django/views/generic/base.py", line 84, in view
    return self.dispatch(request, *args, **kwargs)
  File "/usr/local/lib/python3.8/site-packages/django/views/generic/base.py", line 119, in dispatch
    return handler(request, *args, **kwargs)
  File "/usr/local/lib/python3.8/site-packages/django/views/generic/list.py", line 174, in get
    context = self.get_context_data()
  File "/web_django/women/views.py", line 22, in get_context_data
    context = super().get_context_data(**kwargs)
  File "/usr/local/lib/python3.8/site-packages/django/views/generic/list.py", line 128, in get_context_data
    paginator, page, queryset, is_paginated = self.paginate_queryset(
  File "/usr/local/lib/python3.8/site-packages/django/views/generic/list.py", line 73, in paginate_queryset
    page = paginator.page(page_number)
  File "/usr/local/lib/python3.8/site-packages/django/core/paginator.py", line 75, in page
    number = self.validate_number(number)
  File "/usr/local/lib/python3.8/site-packages/django/core/paginator.py", line 53, in validate_number
    if number > self.num_pages:
  File "/usr/local/lib/python3.8/site-packages/django/utils/functional.py", line 49, in __get__
    res = instance.__dict__[self.name] = self.func(instance)
  File "/usr/local/lib/python3.8/site-packages/django/core/paginator.py", line 102, in num_pages
    if self.count == 0 and not self.allow_empty_first_page:
  File "/usr/local/lib/python3.8/site-packages/django/utils/functional.py", line 49, in __get__
    res = instance.__dict__[self.name] = self.func(instance)
  File "/usr/local/lib/python3.8/site-packages/django/core/paginator.py", line 96, in count
    return c()
  File "/usr/local/lib/python3.8/site-packages/django/db/models/query.py", line 470, in count
    return self.query.get_count(using=self.db)
  File "/usr/local/lib/python3.8/site-packages/django/db/models/sql/query.py", line 552, in get_count
    number = obj.get_aggregation(using, ["__count"])["__count"]
  File "/usr/local/lib/python3.8/site-packages/django/db/models/sql/query.py", line 537, in get_aggregation
    result = compiler.execute_sql(SINGLE)
  File "/usr/local/lib/python3.8/site-packages/django/db/models/sql/compiler.py", line 1361, in execute_sql
    cursor.execute(sql, params)
  File "/usr/local/lib/python3.8/site-packages/django/db/backends/utils.py", line 103, in execute
    return super().execute(sql, params)
  File "/usr/local/lib/python3.8/site-packages/django/db/backends/utils.py", line 67, in execute
    return self._execute_with_wrappers(
  File "/usr/local/lib/python3.8/site-packages/django/db/backends/utils.py", line 80, in _execute_with_wrappers
    return executor(sql, params, many, context)
  File "/usr/local/lib/python3.8/site-packages/django/db/backends/utils.py", line 89, in _execute
    return self.cursor.execute(sql, params)
  File "/usr/local/lib/python3.8/site-packages/django/db/utils.py", line 91, in __exit__
    raise dj_exc_value.with_traceback(traceback) from exc_value
  File "/usr/local/lib/python3.8/site-packages/django/db/backends/utils.py", line 89, in _execute
    return self.cursor.execute(sql, params)
django.db.utils.ProgrammingError: relation "women_women" does not exist
LINE 1: SELECT COUNT(*) AS "__count" FROM "women_women" WHERE "women...
                                          ^

2022-05-23 10:05:35 [ERROR   ] (log.log_response) Internal Server Error: /
Traceback (most recent call last):
  File "/usr/local/lib/python3.8/site-packages/django/db/backends/utils.py", line 89, in _execute
    return self.cursor.execute(sql, params)
psycopg2.errors.UndefinedTable: relation "women_women" does not exist
LINE 1: SELECT COUNT(*) AS "__count" FROM "women_women" WHERE "women...
                                          ^


The above exception was the direct cause of the following exception:

Traceback (most recent call last):
  File "/usr/local/lib/python3.8/site-packages/django/core/handlers/exception.py", line 55, in inner
    response = get_response(request)
  File "/usr/local/lib/python3.8/site-packages/django/core/handlers/base.py", line 197, in _get_response
    response = wrapped_callback(request, *callback_args, **callback_kwargs)
  File "/usr/local/lib/python3.8/site-packages/django/views/generic/base.py", line 84, in view
    return self.dispatch(request, *args, **kwargs)
  File "/usr/local/lib/python3.8/site-packages/django/views/generic/base.py", line 119, in dispatch
    return handler(request, *args, **kwargs)
  File "/usr/local/lib/python3.8/site-packages/django/views/generic/list.py", line 174, in get
    context = self.get_context_data()
  File "/web_django/women/views.py", line 22, in get_context_data
    context = super().get_context_data(**kwargs)
  File "/usr/local/lib/python3.8/site-packages/django/views/generic/list.py", line 128, in get_context_data
    paginator, page, queryset, is_paginated = self.paginate_queryset(
  File "/usr/local/lib/python3.8/site-packages/django/views/generic/list.py", line 73, in paginate_queryset
    page = paginator.page(page_number)
  File "/usr/local/lib/python3.8/site-packages/django/core/paginator.py", line 75, in page
    number = self.validate_number(number)
  File "/usr/local/lib/python3.8/site-packages/django/core/paginator.py", line 53, in validate_number
    if number > self.num_pages:
  File "/usr/local/lib/python3.8/site-packages/django/utils/functional.py", line 49, in __get__
    res = instance.__dict__[self.name] = self.func(instance)
  File "/usr/local/lib/python3.8/site-packages/django/core/paginator.py", line 102, in num_pages
    if self.count == 0 and not self.allow_empty_first_page:
  File "/usr/local/lib/python3.8/site-packages/django/utils/functional.py", line 49, in __get__
    res = instance.__dict__[self.name] = self.func(instance)
  File "/usr/local/lib/python3.8/site-packages/django/core/paginator.py", line 96, in count
    return c()
  File "/usr/local/lib/python3.8/site-packages/django/db/models/query.py", line 470, in count
    return self.query.get_count(using=self.db)
  File "/usr/local/lib/python3.8/site-packages/django/db/models/sql/query.py", line 552, in get_count
    number = obj.get_aggregation(using, ["__count"])["__count"]
  File "/usr/local/lib/python3.8/site-packages/django/db/models/sql/query.py", line 537, in get_aggregation
    result = compiler.execute_sql(SINGLE)
  File "/usr/local/lib/python3.8/site-packages/django/db/models/sql/compiler.py", line 1361, in execute_sql
    cursor.execute(sql, params)
  File "/usr/local/lib/python3.8/site-packages/django/db/backends/utils.py", line 103, in execute
    return super().execute(sql, params)
  File "/usr/local/lib/python3.8/site-packages/django/db/backends/utils.py", line 67, in execute
    return self._execute_with_wrappers(
  File "/usr/local/lib/python3.8/site-packages/django/db/backends/utils.py", line 80, in _execute_with_wrappers
    return executor(sql, params, many, context)
  File "/usr/local/lib/python3.8/site-packages/django/db/backends/utils.py", line 89, in _execute
    return self.cursor.execute(sql, params)
  File "/usr/local/lib/python3.8/site-packages/django/db/utils.py", line 91, in __exit__
    raise dj_exc_value.with_traceback(traceback) from exc_value
  File "/usr/local/lib/python3.8/site-packages/django/db/backends/utils.py", line 89, in _execute
    return self.cursor.execute(sql, params)
django.db.utils.ProgrammingError: relation "women_women" does not exist
LINE 1: SELECT COUNT(*) AS "__count" FROM "women_women" WHERE "women...
                                          ^

2022-05-23 10:05:35 [ERROR   ] (basehttp.log_message) "GET / HTTP/1.1" 500 156860
2022-05-23 10:05:35 [ERROR   ] (basehttp.log_message) "GET / HTTP/1.1" 500 156860
2022-05-24 14:12:54 [ERROR   ] (log.log_response) Internal Server Error: /
Traceback (most recent call last):
  File "/usr/local/lib/python3.8/site-packages/django/db/backends/utils.py", line 89, in _execute
    return self.cursor.execute(sql, params)
psycopg2.errors.UndefinedTable: relation "women_women" does not exist
LINE 1: SELECT COUNT(*) AS "__count" FROM "women_women" WHERE "women...
                                          ^


The above exception was the direct cause of the following exception:

Traceback (most recent call last):
  File "/usr/local/lib/python3.8/site-packages/django/core/handlers/exception.py", line 55, in inner
    response = get_response(request)
  File "/usr/local/lib/python3.8/site-packages/django/core/handlers/base.py", line 197, in _get_response
    response = wrapped_callback(request, *callback_args, **callback_kwargs)
  File "/usr/local/lib/python3.8/site-packages/django/views/generic/base.py", line 84, in view
    return self.dispatch(request, *args, **kwargs)
  File "/usr/local/lib/python3.8/site-packages/django/views/generic/base.py", line 119, in dispatch
    return handler(request, *args, **kwargs)
  File "/usr/local/lib/python3.8/site-packages/django/views/generic/list.py", line 174, in get
    context = self.get_context_data()
  File "/web_django/women/views.py", line 22, in get_context_data
    context = super().get_context_data(**kwargs)
  File "/usr/local/lib/python3.8/site-packages/django/views/generic/list.py", line 128, in get_context_data
    paginator, page, queryset, is_paginated = self.paginate_queryset(
  File "/usr/local/lib/python3.8/site-packages/django/views/generic/list.py", line 73, in paginate_queryset
    page = paginator.page(page_number)
  File "/usr/local/lib/python3.8/site-packages/django/core/paginator.py", line 75, in page
    number = self.validate_number(number)
  File "/usr/local/lib/python3.8/site-packages/django/core/paginator.py", line 53, in validate_number
    if number > self.num_pages:
  File "/usr/local/lib/python3.8/site-packages/django/utils/functional.py", line 49, in __get__
    res = instance.__dict__[self.name] = self.func(instance)
  File "/usr/local/lib/python3.8/site-packages/django/core/paginator.py", line 102, in num_pages
    if self.count == 0 and not self.allow_empty_first_page:
  File "/usr/local/lib/python3.8/site-packages/django/utils/functional.py", line 49, in __get__
    res = instance.__dict__[self.name] = self.func(instance)
  File "/usr/local/lib/python3.8/site-packages/django/core/paginator.py", line 96, in count
    return c()
  File "/usr/local/lib/python3.8/site-packages/django/db/models/query.py", line 470, in count
    return self.query.get_count(using=self.db)
  File "/usr/local/lib/python3.8/site-packages/django/db/models/sql/query.py", line 552, in get_count
    number = obj.get_aggregation(using, ["__count"])["__count"]
  File "/usr/local/lib/python3.8/site-packages/django/db/models/sql/query.py", line 537, in get_aggregation
    result = compiler.execute_sql(SINGLE)
  File "/usr/local/lib/python3.8/site-packages/django/db/models/sql/compiler.py", line 1361, in execute_sql
    cursor.execute(sql, params)
  File "/usr/local/lib/python3.8/site-packages/django/db/backends/utils.py", line 103, in execute
    return super().execute(sql, params)
  File "/usr/local/lib/python3.8/site-packages/django/db/backends/utils.py", line 67, in execute
    return self._execute_with_wrappers(
  File "/usr/local/lib/python3.8/site-packages/django/db/backends/utils.py", line 80, in _execute_with_wrappers
    return executor(sql, params, many, context)
  File "/usr/local/lib/python3.8/site-packages/django/db/backends/utils.py", line 89, in _execute
    return self.cursor.execute(sql, params)
  File "/usr/local/lib/python3.8/site-packages/django/db/utils.py", line 91, in __exit__
    raise dj_exc_value.with_traceback(traceback) from exc_value
  File "/usr/local/lib/python3.8/site-packages/django/db/backends/utils.py", line 89, in _execute
    return self.cursor.execute(sql, params)
django.db.utils.ProgrammingError: relation "women_women" does not exist
LINE 1: SELECT COUNT(*) AS "__count" FROM "women_women" WHERE "women...
                                          ^

2022-05-24 14:12:54 [ERROR   ] (log.log_response) Internal Server Error: /
Traceback (most recent call last):
  File "/usr/local/lib/python3.8/site-packages/django/db/backends/utils.py", line 89, in _execute
    return self.cursor.execute(sql, params)
psycopg2.errors.UndefinedTable: relation "women_women" does not exist
LINE 1: SELECT COUNT(*) AS "__count" FROM "women_women" WHERE "women...
                                          ^


The above exception was the direct cause of the following exception:

Traceback (most recent call last):
  File "/usr/local/lib/python3.8/site-packages/django/core/handlers/exception.py", line 55, in inner
    response = get_response(request)
  File "/usr/local/lib/python3.8/site-packages/django/core/handlers/base.py", line 197, in _get_response
    response = wrapped_callback(request, *callback_args, **callback_kwargs)
  File "/usr/local/lib/python3.8/site-packages/django/views/generic/base.py", line 84, in view
    return self.dispatch(request, *args, **kwargs)
  File "/usr/local/lib/python3.8/site-packages/django/views/generic/base.py", line 119, in dispatch
    return handler(request, *args, **kwargs)
  File "/usr/local/lib/python3.8/site-packages/django/views/generic/list.py", line 174, in get
    context = self.get_context_data()
  File "/web_django/women/views.py", line 22, in get_context_data
    context = super().get_context_data(**kwargs)
  File "/usr/local/lib/python3.8/site-packages/django/views/generic/list.py", line 128, in get_context_data
    paginator, page, queryset, is_paginated = self.paginate_queryset(
  File "/usr/local/lib/python3.8/site-packages/django/views/generic/list.py", line 73, in paginate_queryset
    page = paginator.page(page_number)
  File "/usr/local/lib/python3.8/site-packages/django/core/paginator.py", line 75, in page
    number = self.validate_number(number)
  File "/usr/local/lib/python3.8/site-packages/django/core/paginator.py", line 53, in validate_number
    if number > self.num_pages:
  File "/usr/local/lib/python3.8/site-packages/django/utils/functional.py", line 49, in __get__
    res = instance.__dict__[self.name] = self.func(instance)
  File "/usr/local/lib/python3.8/site-packages/django/core/paginator.py", line 102, in num_pages
    if self.count == 0 and not self.allow_empty_first_page:
  File "/usr/local/lib/python3.8/site-packages/django/utils/functional.py", line 49, in __get__
    res = instance.__dict__[self.name] = self.func(instance)
  File "/usr/local/lib/python3.8/site-packages/django/core/paginator.py", line 96, in count
    return c()
  File "/usr/local/lib/python3.8/site-packages/django/db/models/query.py", line 470, in count
    return self.query.get_count(using=self.db)
  File "/usr/local/lib/python3.8/site-packages/django/db/models/sql/query.py", line 552, in get_count
    number = obj.get_aggregation(using, ["__count"])["__count"]
  File "/usr/local/lib/python3.8/site-packages/django/db/models/sql/query.py", line 537, in get_aggregation
    result = compiler.execute_sql(SINGLE)
  File "/usr/local/lib/python3.8/site-packages/django/db/models/sql/compiler.py", line 1361, in execute_sql
    cursor.execute(sql, params)
  File "/usr/local/lib/python3.8/site-packages/django/db/backends/utils.py", line 103, in execute
    return super().execute(sql, params)
  File "/usr/local/lib/python3.8/site-packages/django/db/backends/utils.py", line 67, in execute
    return self._execute_with_wrappers(
  File "/usr/local/lib/python3.8/site-packages/django/db/backends/utils.py", line 80, in _execute_with_wrappers
    return executor(sql, params, many, context)
  File "/usr/local/lib/python3.8/site-packages/django/db/backends/utils.py", line 89, in _execute
    return self.cursor.execute(sql, params)
  File "/usr/local/lib/python3.8/site-packages/django/db/utils.py", line 91, in __exit__
    raise dj_exc_value.with_traceback(traceback) from exc_value
  File "/usr/local/lib/python3.8/site-packages/django/db/backends/utils.py", line 89, in _execute
    return self.cursor.execute(sql, params)
django.db.utils.ProgrammingError: relation "women_women" does not exist
LINE 1: SELECT COUNT(*) AS "__count" FROM "women_women" WHERE "women...
                                          ^

2022-05-24 14:12:54 [ERROR   ] (basehttp.log_message) "GET / HTTP/1.1" 500 156860
2022-05-24 14:12:54 [ERROR   ] (basehttp.log_message) "GET / HTTP/1.1" 500 156860
2022-05-24 19:01:24 [ERROR   ] (log.log_response) Internal Server Error: /addpage/
Traceback (most recent call last):
  File "/usr/local/lib/python3.8/site-packages/django/contrib/sessions/backends/base.py", line 187, in _get_session
    return self._session_cache
AttributeError: 'SessionStore' object has no attribute '_session_cache'

During handling of the above exception, another exception occurred:

Traceback (most recent call last):
  File "/usr/local/lib/python3.8/site-packages/django/db/backends/utils.py", line 89, in _execute
    return self.cursor.execute(sql, params)
psycopg2.errors.UndefinedTable: relation "django_session" does not exist
LINE 1: ...ession_data", "django_session"."expire_date" FROM "django_se...
                                                             ^


The above exception was the direct cause of the following exception:

Traceback (most recent call last):
  File "/usr/local/lib/python3.8/site-packages/django/core/handlers/exception.py", line 55, in inner
    response = get_response(request)
  File "/usr/local/lib/python3.8/site-packages/django/core/handlers/base.py", line 197, in _get_response
    response = wrapped_callback(request, *callback_args, **callback_kwargs)
  File "/usr/local/lib/python3.8/site-packages/django/views/generic/base.py", line 84, in view
    return self.dispatch(request, *args, **kwargs)
  File "/usr/local/lib/python3.8/site-packages/django/contrib/auth/mixins.py", line 71, in dispatch
    if not request.user.is_authenticated:
  File "/usr/local/lib/python3.8/site-packages/django/utils/functional.py", line 258, in inner
    self._setup()
  File "/usr/local/lib/python3.8/site-packages/django/utils/functional.py", line 398, in _setup
    self._wrapped = self._setupfunc()
  File "/usr/local/lib/python3.8/site-packages/django/contrib/auth/middleware.py", line 25, in <lambda>
    request.user = SimpleLazyObject(lambda: get_user(request))
  File "/usr/local/lib/python3.8/site-packages/django/contrib/auth/middleware.py", line 11, in get_user
    request._cached_user = auth.get_user(request)
  File "/usr/local/lib/python3.8/site-packages/django/contrib/auth/__init__.py", line 191, in get_user
    user_id = _get_user_session_key(request)
  File "/usr/local/lib/python3.8/site-packages/django/contrib/auth/__init__.py", line 60, in _get_user_session_key
    return get_user_model()._meta.pk.to_python(request.session[SESSION_KEY])
  File "/usr/local/lib/python3.8/site-packages/django/contrib/sessions/backends/base.py", line 53, in __getitem__
    return self._session[key]
  File "/usr/local/lib/python3.8/site-packages/django/contrib/sessions/backends/base.py", line 192, in _get_session
    self._session_cache = self.load()
  File "/usr/local/lib/python3.8/site-packages/django/contrib/sessions/backends/db.py", line 42, in load
    s = self._get_session_from_db()
  File "/usr/local/lib/python3.8/site-packages/django/contrib/sessions/backends/db.py", line 32, in _get_session_from_db
    return self.model.objects.get(
  File "/usr/local/lib/python3.8/site-packages/django/db/models/manager.py", line 85, in manager_method
    return getattr(self.get_queryset(), name)(*args, **kwargs)
  File "/usr/local/lib/python3.8/site-packages/django/db/models/query.py", line 492, in get
    num = len(clone)
  File "/usr/local/lib/python3.8/site-packages/django/db/models/query.py", line 302, in __len__
    self._fetch_all()
  File "/usr/local/lib/python3.8/site-packages/django/db/models/query.py", line 1507, in _fetch_all
    self._result_cache = list(self._iterable_class(self))
  File "/usr/local/lib/python3.8/site-packages/django/db/models/query.py", line 57, in __iter__
    results = compiler.execute_sql(
  File "/usr/local/lib/python3.8/site-packages/django/db/models/sql/compiler.py", line 1361, in execute_sql
    cursor.execute(sql, params)
  File "/usr/local/lib/python3.8/site-packages/django/db/backends/utils.py", line 103, in execute
    return super().execute(sql, params)
  File "/usr/local/lib/python3.8/site-packages/django/db/backends/utils.py", line 67, in execute
    return self._execute_with_wrappers(
  File "/usr/local/lib/python3.8/site-packages/django/db/backends/utils.py", line 80, in _execute_with_wrappers
    return executor(sql, params, many, context)
  File "/usr/local/lib/python3.8/site-packages/django/db/backends/utils.py", line 89, in _execute
    return self.cursor.execute(sql, params)
  File "/usr/local/lib/python3.8/site-packages/django/db/utils.py", line 91, in __exit__
    raise dj_exc_value.with_traceback(traceback) from exc_value
  File "/usr/local/lib/python3.8/site-packages/django/db/backends/utils.py", line 89, in _execute
    return self.cursor.execute(sql, params)
django.db.utils.ProgrammingError: relation "django_session" does not exist
LINE 1: ...ession_data", "django_session"."expire_date" FROM "django_se...
                                                             ^

2022-05-24 19:01:24 [ERROR   ] (log.log_response) Internal Server Error: /addpage/
Traceback (most recent call last):
  File "/usr/local/lib/python3.8/site-packages/django/contrib/sessions/backends/base.py", line 187, in _get_session
    return self._session_cache
AttributeError: 'SessionStore' object has no attribute '_session_cache'

During handling of the above exception, another exception occurred:

Traceback (most recent call last):
  File "/usr/local/lib/python3.8/site-packages/django/db/backends/utils.py", line 89, in _execute
    return self.cursor.execute(sql, params)
psycopg2.errors.UndefinedTable: relation "django_session" does not exist
LINE 1: ...ession_data", "django_session"."expire_date" FROM "django_se...
                                                             ^


The above exception was the direct cause of the following exception:

Traceback (most recent call last):
  File "/usr/local/lib/python3.8/site-packages/django/core/handlers/exception.py", line 55, in inner
    response = get_response(request)
  File "/usr/local/lib/python3.8/site-packages/django/core/handlers/base.py", line 197, in _get_response
    response = wrapped_callback(request, *callback_args, **callback_kwargs)
  File "/usr/local/lib/python3.8/site-packages/django/views/generic/base.py", line 84, in view
    return self.dispatch(request, *args, **kwargs)
  File "/usr/local/lib/python3.8/site-packages/django/contrib/auth/mixins.py", line 71, in dispatch
    if not request.user.is_authenticated:
  File "/usr/local/lib/python3.8/site-packages/django/utils/functional.py", line 258, in inner
    self._setup()
  File "/usr/local/lib/python3.8/site-packages/django/utils/functional.py", line 398, in _setup
    self._wrapped = self._setupfunc()
  File "/usr/local/lib/python3.8/site-packages/django/contrib/auth/middleware.py", line 25, in <lambda>
    request.user = SimpleLazyObject(lambda: get_user(request))
  File "/usr/local/lib/python3.8/site-packages/django/contrib/auth/middleware.py", line 11, in get_user
    request._cached_user = auth.get_user(request)
  File "/usr/local/lib/python3.8/site-packages/django/contrib/auth/__init__.py", line 191, in get_user
    user_id = _get_user_session_key(request)
  File "/usr/local/lib/python3.8/site-packages/django/contrib/auth/__init__.py", line 60, in _get_user_session_key
    return get_user_model()._meta.pk.to_python(request.session[SESSION_KEY])
  File "/usr/local/lib/python3.8/site-packages/django/contrib/sessions/backends/base.py", line 53, in __getitem__
    return self._session[key]
  File "/usr/local/lib/python3.8/site-packages/django/contrib/sessions/backends/base.py", line 192, in _get_session
    self._session_cache = self.load()
  File "/usr/local/lib/python3.8/site-packages/django/contrib/sessions/backends/db.py", line 42, in load
    s = self._get_session_from_db()
  File "/usr/local/lib/python3.8/site-packages/django/contrib/sessions/backends/db.py", line 32, in _get_session_from_db
    return self.model.objects.get(
  File "/usr/local/lib/python3.8/site-packages/django/db/models/manager.py", line 85, in manager_method
    return getattr(self.get_queryset(), name)(*args, **kwargs)
  File "/usr/local/lib/python3.8/site-packages/django/db/models/query.py", line 492, in get
    num = len(clone)
  File "/usr/local/lib/python3.8/site-packages/django/db/models/query.py", line 302, in __len__
    self._fetch_all()
  File "/usr/local/lib/python3.8/site-packages/django/db/models/query.py", line 1507, in _fetch_all
    self._result_cache = list(self._iterable_class(self))
  File "/usr/local/lib/python3.8/site-packages/django/db/models/query.py", line 57, in __iter__
    results = compiler.execute_sql(
  File "/usr/local/lib/python3.8/site-packages/django/db/models/sql/compiler.py", line 1361, in execute_sql
    cursor.execute(sql, params)
  File "/usr/local/lib/python3.8/site-packages/django/db/backends/utils.py", line 103, in execute
    return super().execute(sql, params)
  File "/usr/local/lib/python3.8/site-packages/django/db/backends/utils.py", line 67, in execute
    return self._execute_with_wrappers(
  File "/usr/local/lib/python3.8/site-packages/django/db/backends/utils.py", line 80, in _execute_with_wrappers
    return executor(sql, params, many, context)
  File "/usr/local/lib/python3.8/site-packages/django/db/backends/utils.py", line 89, in _execute
    return self.cursor.execute(sql, params)
  File "/usr/local/lib/python3.8/site-packages/django/db/utils.py", line 91, in __exit__
    raise dj_exc_value.with_traceback(traceback) from exc_value
  File "/usr/local/lib/python3.8/site-packages/django/db/backends/utils.py", line 89, in _execute
    return self.cursor.execute(sql, params)
django.db.utils.ProgrammingError: relation "django_session" does not exist
LINE 1: ...ession_data", "django_session"."expire_date" FROM "django_se...
                                                             ^

2022-05-24 19:01:24 [ERROR   ] (basehttp.log_message) "GET /addpage/ HTTP/1.1" 500 168475
2022-05-24 19:01:24 [ERROR   ] (basehttp.log_message) "GET /addpage/ HTTP/1.1" 500 168475
2022-05-24 19:01:36 [ERROR   ] (log.log_response) Internal Server Error: /
Traceback (most recent call last):
  File "/usr/local/lib/python3.8/site-packages/django/db/backends/utils.py", line 89, in _execute
    return self.cursor.execute(sql, params)
psycopg2.errors.UndefinedTable: relation "women_women" does not exist
LINE 1: SELECT COUNT(*) AS "__count" FROM "women_women" WHERE "women...
                                          ^


The above exception was the direct cause of the following exception:

Traceback (most recent call last):
  File "/usr/local/lib/python3.8/site-packages/django/core/handlers/exception.py", line 55, in inner
    response = get_response(request)
  File "/usr/local/lib/python3.8/site-packages/django/core/handlers/base.py", line 197, in _get_response
    response = wrapped_callback(request, *callback_args, **callback_kwargs)
  File "/usr/local/lib/python3.8/site-packages/django/views/generic/base.py", line 84, in view
    return self.dispatch(request, *args, **kwargs)
  File "/usr/local/lib/python3.8/site-packages/django/views/generic/base.py", line 119, in dispatch
    return handler(request, *args, **kwargs)
  File "/usr/local/lib/python3.8/site-packages/django/views/generic/list.py", line 174, in get
    context = self.get_context_data()
  File "/web_django/women/views.py", line 22, in get_context_data
    context = super().get_context_data(**kwargs)
  File "/usr/local/lib/python3.8/site-packages/django/views/generic/list.py", line 128, in get_context_data
    paginator, page, queryset, is_paginated = self.paginate_queryset(
  File "/usr/local/lib/python3.8/site-packages/django/views/generic/list.py", line 73, in paginate_queryset
    page = paginator.page(page_number)
  File "/usr/local/lib/python3.8/site-packages/django/core/paginator.py", line 75, in page
    number = self.validate_number(number)
  File "/usr/local/lib/python3.8/site-packages/django/core/paginator.py", line 53, in validate_number
    if number > self.num_pages:
  File "/usr/local/lib/python3.8/site-packages/django/utils/functional.py", line 49, in __get__
    res = instance.__dict__[self.name] = self.func(instance)
  File "/usr/local/lib/python3.8/site-packages/django/core/paginator.py", line 102, in num_pages
    if self.count == 0 and not self.allow_empty_first_page:
  File "/usr/local/lib/python3.8/site-packages/django/utils/functional.py", line 49, in __get__
    res = instance.__dict__[self.name] = self.func(instance)
  File "/usr/local/lib/python3.8/site-packages/django/core/paginator.py", line 96, in count
    return c()
  File "/usr/local/lib/python3.8/site-packages/django/db/models/query.py", line 470, in count
    return self.query.get_count(using=self.db)
  File "/usr/local/lib/python3.8/site-packages/django/db/models/sql/query.py", line 552, in get_count
    number = obj.get_aggregation(using, ["__count"])["__count"]
  File "/usr/local/lib/python3.8/site-packages/django/db/models/sql/query.py", line 537, in get_aggregation
    result = compiler.execute_sql(SINGLE)
  File "/usr/local/lib/python3.8/site-packages/django/db/models/sql/compiler.py", line 1361, in execute_sql
    cursor.execute(sql, params)
  File "/usr/local/lib/python3.8/site-packages/django/db/backends/utils.py", line 103, in execute
    return super().execute(sql, params)
  File "/usr/local/lib/python3.8/site-packages/django/db/backends/utils.py", line 67, in execute
    return self._execute_with_wrappers(
  File "/usr/local/lib/python3.8/site-packages/django/db/backends/utils.py", line 80, in _execute_with_wrappers
    return executor(sql, params, many, context)
  File "/usr/local/lib/python3.8/site-packages/django/db/backends/utils.py", line 89, in _execute
    return self.cursor.execute(sql, params)
  File "/usr/local/lib/python3.8/site-packages/django/db/utils.py", line 91, in __exit__
    raise dj_exc_value.with_traceback(traceback) from exc_value
  File "/usr/local/lib/python3.8/site-packages/django/db/backends/utils.py", line 89, in _execute
    return self.cursor.execute(sql, params)
django.db.utils.ProgrammingError: relation "women_women" does not exist
LINE 1: SELECT COUNT(*) AS "__count" FROM "women_women" WHERE "women...
                                          ^

2022-05-24 19:01:36 [ERROR   ] (log.log_response) Internal Server Error: /
Traceback (most recent call last):
  File "/usr/local/lib/python3.8/site-packages/django/db/backends/utils.py", line 89, in _execute
    return self.cursor.execute(sql, params)
psycopg2.errors.UndefinedTable: relation "women_women" does not exist
LINE 1: SELECT COUNT(*) AS "__count" FROM "women_women" WHERE "women...
                                          ^


The above exception was the direct cause of the following exception:

Traceback (most recent call last):
  File "/usr/local/lib/python3.8/site-packages/django/core/handlers/exception.py", line 55, in inner
    response = get_response(request)
  File "/usr/local/lib/python3.8/site-packages/django/core/handlers/base.py", line 197, in _get_response
    response = wrapped_callback(request, *callback_args, **callback_kwargs)
  File "/usr/local/lib/python3.8/site-packages/django/views/generic/base.py", line 84, in view
    return self.dispatch(request, *args, **kwargs)
  File "/usr/local/lib/python3.8/site-packages/django/views/generic/base.py", line 119, in dispatch
    return handler(request, *args, **kwargs)
  File "/usr/local/lib/python3.8/site-packages/django/views/generic/list.py", line 174, in get
    context = self.get_context_data()
  File "/web_django/women/views.py", line 22, in get_context_data
    context = super().get_context_data(**kwargs)
  File "/usr/local/lib/python3.8/site-packages/django/views/generic/list.py", line 128, in get_context_data
    paginator, page, queryset, is_paginated = self.paginate_queryset(
  File "/usr/local/lib/python3.8/site-packages/django/views/generic/list.py", line 73, in paginate_queryset
    page = paginator.page(page_number)
  File "/usr/local/lib/python3.8/site-packages/django/core/paginator.py", line 75, in page
    number = self.validate_number(number)
  File "/usr/local/lib/python3.8/site-packages/django/core/paginator.py", line 53, in validate_number
    if number > self.num_pages:
  File "/usr/local/lib/python3.8/site-packages/django/utils/functional.py", line 49, in __get__
    res = instance.__dict__[self.name] = self.func(instance)
  File "/usr/local/lib/python3.8/site-packages/django/core/paginator.py", line 102, in num_pages
    if self.count == 0 and not self.allow_empty_first_page:
  File "/usr/local/lib/python3.8/site-packages/django/utils/functional.py", line 49, in __get__
    res = instance.__dict__[self.name] = self.func(instance)
  File "/usr/local/lib/python3.8/site-packages/django/core/paginator.py", line 96, in count
    return c()
  File "/usr/local/lib/python3.8/site-packages/django/db/models/query.py", line 470, in count
    return self.query.get_count(using=self.db)
  File "/usr/local/lib/python3.8/site-packages/django/db/models/sql/query.py", line 552, in get_count
    number = obj.get_aggregation(using, ["__count"])["__count"]
  File "/usr/local/lib/python3.8/site-packages/django/db/models/sql/query.py", line 537, in get_aggregation
    result = compiler.execute_sql(SINGLE)
  File "/usr/local/lib/python3.8/site-packages/django/db/models/sql/compiler.py", line 1361, in execute_sql
    cursor.execute(sql, params)
  File "/usr/local/lib/python3.8/site-packages/django/db/backends/utils.py", line 103, in execute
    return super().execute(sql, params)
  File "/usr/local/lib/python3.8/site-packages/django/db/backends/utils.py", line 67, in execute
    return self._execute_with_wrappers(
  File "/usr/local/lib/python3.8/site-packages/django/db/backends/utils.py", line 80, in _execute_with_wrappers
    return executor(sql, params, many, context)
  File "/usr/local/lib/python3.8/site-packages/django/db/backends/utils.py", line 89, in _execute
    return self.cursor.execute(sql, params)
  File "/usr/local/lib/python3.8/site-packages/django/db/utils.py", line 91, in __exit__
    raise dj_exc_value.with_traceback(traceback) from exc_value
  File "/usr/local/lib/python3.8/site-packages/django/db/backends/utils.py", line 89, in _execute
    return self.cursor.execute(sql, params)
django.db.utils.ProgrammingError: relation "women_women" does not exist
LINE 1: SELECT COUNT(*) AS "__count" FROM "women_women" WHERE "women...
                                          ^

2022-05-24 19:01:36 [ERROR   ] (basehttp.log_message) "GET / HTTP/1.1" 500 156860
2022-05-24 19:01:36 [ERROR   ] (basehttp.log_message) "GET / HTTP/1.1" 500 156860
