2022-05-19 19:31:23 [ERROR   ] (exception.response_for_exception) Invalid HTTP_HOST header: '0.0.0.0:8000'. You may need to add '0.0.0.0' to ALLOWED_HOSTS.
2022-05-19 19:31:23 [ERROR   ] (exception.response_for_exception) Invalid HTTP_HOST header: '0.0.0.0:8000'. You may need to add '0.0.0.0' to ALLOWED_HOSTS.
2022-05-19 19:31:25 [ERROR   ] (exception.response_for_exception) Invalid HTTP_HOST header: '0.0.0.0:8000'. You may need to add '0.0.0.0' to ALLOWED_HOSTS.
2022-05-19 19:31:25 [ERROR   ] (exception.response_for_exception) Invalid HTTP_HOST header: '0.0.0.0:8000'. You may need to add '0.0.0.0' to ALLOWED_HOSTS.
2022-05-19 19:31:34 [ERROR   ] (log.log_response) Internal Server Error: /
Traceback (most recent call last):
  File "/usr/local/lib/python3.8/site-packages/django/db/backends/utils.py", line 89, in _execute
    return self.cursor.execute(sql, params)
  File "/usr/local/lib/python3.8/site-packages/django/db/backends/mysql/base.py", line 75, in execute
    return self.cursor.execute(query, args)
  File "/usr/local/lib/python3.8/site-packages/MySQLdb/cursors.py", line 206, in execute
    res = self._query(query)
  File "/usr/local/lib/python3.8/site-packages/MySQLdb/cursors.py", line 319, in _query
    db.query(q)
  File "/usr/local/lib/python3.8/site-packages/MySQLdb/connections.py", line 254, in query
    _mysql.connection.query(self, query)
MySQLdb._exceptions.ProgrammingError: (1146, "Table 'db_django.women_women' doesn't exist")

The above exception was the direct cause of the following exception:

Traceback (most recent call last):
  File "/usr/local/lib/python3.8/site-packages/django/core/handlers/exception.py", line 55, in inner
    response = get_response(request)
  File "/usr/local/lib/python3.8/site-packages/django/core/handlers/base.py", line 197, in _get_response
    response = wrapped_callback(request, *callback_args, **callback_kwargs)
  File "/usr/local/lib/python3.8/site-packages/django/views/generic/base.py", line 84, in view
    return self.dispatch(request, *args, **kwargs)
  File "/usr/local/lib/python3.8/site-packages/django/views/generic/base.py", line 119, in dispatch
    return handler(request, *args, **kwargs)
  File "/usr/local/lib/python3.8/site-packages/django/views/generic/list.py", line 174, in get
    context = self.get_context_data()
  File "/web_django/women/views.py", line 22, in get_context_data
    context = super().get_context_data(**kwargs)
  File "/usr/local/lib/python3.8/site-packages/django/views/generic/list.py", line 128, in get_context_data
    paginator, page, queryset, is_paginated = self.paginate_queryset(
  File "/usr/local/lib/python3.8/site-packages/django/views/generic/list.py", line 73, in paginate_queryset
    page = paginator.page(page_number)
  File "/usr/local/lib/python3.8/site-packages/django/core/paginator.py", line 75, in page
    number = self.validate_number(number)
  File "/usr/local/lib/python3.8/site-packages/django/core/paginator.py", line 53, in validate_number
    if number > self.num_pages:
  File "/usr/local/lib/python3.8/site-packages/django/utils/functional.py", line 49, in __get__
    res = instance.__dict__[self.name] = self.func(instance)
  File "/usr/local/lib/python3.8/site-packages/django/core/paginator.py", line 102, in num_pages
    if self.count == 0 and not self.allow_empty_first_page:
  File "/usr/local/lib/python3.8/site-packages/django/utils/functional.py", line 49, in __get__
    res = instance.__dict__[self.name] = self.func(instance)
  File "/usr/local/lib/python3.8/site-packages/django/core/paginator.py", line 96, in count
    return c()
  File "/usr/local/lib/python3.8/site-packages/django/db/models/query.py", line 470, in count
    return self.query.get_count(using=self.db)
  File "/usr/local/lib/python3.8/site-packages/django/db/models/sql/query.py", line 552, in get_count
    number = obj.get_aggregation(using, ["__count"])["__count"]
  File "/usr/local/lib/python3.8/site-packages/django/db/models/sql/query.py", line 537, in get_aggregation
    result = compiler.execute_sql(SINGLE)
  File "/usr/local/lib/python3.8/site-packages/django/db/models/sql/compiler.py", line 1361, in execute_sql
    cursor.execute(sql, params)
  File "/usr/local/lib/python3.8/site-packages/django/db/backends/utils.py", line 103, in execute
    return super().execute(sql, params)
  File "/usr/local/lib/python3.8/site-packages/django/db/backends/utils.py", line 67, in execute
    return self._execute_with_wrappers(
  File "/usr/local/lib/python3.8/site-packages/django/db/backends/utils.py", line 80, in _execute_with_wrappers
    return executor(sql, params, many, context)
  File "/usr/local/lib/python3.8/site-packages/django/db/backends/utils.py", line 89, in _execute
    return self.cursor.execute(sql, params)
  File "/usr/local/lib/python3.8/site-packages/django/db/utils.py", line 91, in __exit__
    raise dj_exc_value.with_traceback(traceback) from exc_value
  File "/usr/local/lib/python3.8/site-packages/django/db/backends/utils.py", line 89, in _execute
    return self.cursor.execute(sql, params)
  File "/usr/local/lib/python3.8/site-packages/django/db/backends/mysql/base.py", line 75, in execute
    return self.cursor.execute(query, args)
  File "/usr/local/lib/python3.8/site-packages/MySQLdb/cursors.py", line 206, in execute
    res = self._query(query)
  File "/usr/local/lib/python3.8/site-packages/MySQLdb/cursors.py", line 319, in _query
    db.query(q)
  File "/usr/local/lib/python3.8/site-packages/MySQLdb/connections.py", line 254, in query
    _mysql.connection.query(self, query)
django.db.utils.ProgrammingError: (1146, "Table 'db_django.women_women' doesn't exist")
2022-05-19 19:31:34 [ERROR   ] (log.log_response) Internal Server Error: /
Traceback (most recent call last):
  File "/usr/local/lib/python3.8/site-packages/django/db/backends/utils.py", line 89, in _execute
    return self.cursor.execute(sql, params)
  File "/usr/local/lib/python3.8/site-packages/django/db/backends/mysql/base.py", line 75, in execute
    return self.cursor.execute(query, args)
  File "/usr/local/lib/python3.8/site-packages/MySQLdb/cursors.py", line 206, in execute
    res = self._query(query)
  File "/usr/local/lib/python3.8/site-packages/MySQLdb/cursors.py", line 319, in _query
    db.query(q)
  File "/usr/local/lib/python3.8/site-packages/MySQLdb/connections.py", line 254, in query
    _mysql.connection.query(self, query)
MySQLdb._exceptions.ProgrammingError: (1146, "Table 'db_django.women_women' doesn't exist")

The above exception was the direct cause of the following exception:

Traceback (most recent call last):
  File "/usr/local/lib/python3.8/site-packages/django/core/handlers/exception.py", line 55, in inner
    response = get_response(request)
  File "/usr/local/lib/python3.8/site-packages/django/core/handlers/base.py", line 197, in _get_response
    response = wrapped_callback(request, *callback_args, **callback_kwargs)
  File "/usr/local/lib/python3.8/site-packages/django/views/generic/base.py", line 84, in view
    return self.dispatch(request, *args, **kwargs)
  File "/usr/local/lib/python3.8/site-packages/django/views/generic/base.py", line 119, in dispatch
    return handler(request, *args, **kwargs)
  File "/usr/local/lib/python3.8/site-packages/django/views/generic/list.py", line 174, in get
    context = self.get_context_data()
  File "/web_django/women/views.py", line 22, in get_context_data
    context = super().get_context_data(**kwargs)
  File "/usr/local/lib/python3.8/site-packages/django/views/generic/list.py", line 128, in get_context_data
    paginator, page, queryset, is_paginated = self.paginate_queryset(
  File "/usr/local/lib/python3.8/site-packages/django/views/generic/list.py", line 73, in paginate_queryset
    page = paginator.page(page_number)
  File "/usr/local/lib/python3.8/site-packages/django/core/paginator.py", line 75, in page
    number = self.validate_number(number)
  File "/usr/local/lib/python3.8/site-packages/django/core/paginator.py", line 53, in validate_number
    if number > self.num_pages:
  File "/usr/local/lib/python3.8/site-packages/django/utils/functional.py", line 49, in __get__
    res = instance.__dict__[self.name] = self.func(instance)
  File "/usr/local/lib/python3.8/site-packages/django/core/paginator.py", line 102, in num_pages
    if self.count == 0 and not self.allow_empty_first_page:
  File "/usr/local/lib/python3.8/site-packages/django/utils/functional.py", line 49, in __get__
    res = instance.__dict__[self.name] = self.func(instance)
  File "/usr/local/lib/python3.8/site-packages/django/core/paginator.py", line 96, in count
    return c()
  File "/usr/local/lib/python3.8/site-packages/django/db/models/query.py", line 470, in count
    return self.query.get_count(using=self.db)
  File "/usr/local/lib/python3.8/site-packages/django/db/models/sql/query.py", line 552, in get_count
    number = obj.get_aggregation(using, ["__count"])["__count"]
  File "/usr/local/lib/python3.8/site-packages/django/db/models/sql/query.py", line 537, in get_aggregation
    result = compiler.execute_sql(SINGLE)
  File "/usr/local/lib/python3.8/site-packages/django/db/models/sql/compiler.py", line 1361, in execute_sql
    cursor.execute(sql, params)
  File "/usr/local/lib/python3.8/site-packages/django/db/backends/utils.py", line 103, in execute
    return super().execute(sql, params)
  File "/usr/local/lib/python3.8/site-packages/django/db/backends/utils.py", line 67, in execute
    return self._execute_with_wrappers(
  File "/usr/local/lib/python3.8/site-packages/django/db/backends/utils.py", line 80, in _execute_with_wrappers
    return executor(sql, params, many, context)
  File "/usr/local/lib/python3.8/site-packages/django/db/backends/utils.py", line 89, in _execute
    return self.cursor.execute(sql, params)
  File "/usr/local/lib/python3.8/site-packages/django/db/utils.py", line 91, in __exit__
    raise dj_exc_value.with_traceback(traceback) from exc_value
  File "/usr/local/lib/python3.8/site-packages/django/db/backends/utils.py", line 89, in _execute
    return self.cursor.execute(sql, params)
  File "/usr/local/lib/python3.8/site-packages/django/db/backends/mysql/base.py", line 75, in execute
    return self.cursor.execute(query, args)
  File "/usr/local/lib/python3.8/site-packages/MySQLdb/cursors.py", line 206, in execute
    res = self._query(query)
  File "/usr/local/lib/python3.8/site-packages/MySQLdb/cursors.py", line 319, in _query
    db.query(q)
  File "/usr/local/lib/python3.8/site-packages/MySQLdb/connections.py", line 254, in query
    _mysql.connection.query(self, query)
django.db.utils.ProgrammingError: (1146, "Table 'db_django.women_women' doesn't exist")
2022-05-19 19:31:34 [ERROR   ] (basehttp.log_message) "GET / HTTP/1.1" 500 187070
2022-05-19 19:31:34 [ERROR   ] (basehttp.log_message) "GET / HTTP/1.1" 500 187070
2022-05-19 20:19:14 [ERROR   ] (log.log_response) Internal Server Error: /
Traceback (most recent call last):
  File "/usr/local/lib/python3.8/site-packages/django/db/backends/utils.py", line 89, in _execute
    return self.cursor.execute(sql, params)
psycopg2.errors.UndefinedTable: relation "women_women" does not exist
LINE 1: SELECT COUNT(*) AS "__count" FROM "women_women" WHERE "women...
                                          ^


The above exception was the direct cause of the following exception:

Traceback (most recent call last):
  File "/usr/local/lib/python3.8/site-packages/django/core/handlers/exception.py", line 55, in inner
    response = get_response(request)
  File "/usr/local/lib/python3.8/site-packages/django/core/handlers/base.py", line 197, in _get_response
    response = wrapped_callback(request, *callback_args, **callback_kwargs)
  File "/usr/local/lib/python3.8/site-packages/django/views/generic/base.py", line 84, in view
    return self.dispatch(request, *args, **kwargs)
  File "/usr/local/lib/python3.8/site-packages/django/views/generic/base.py", line 119, in dispatch
    return handler(request, *args, **kwargs)
  File "/usr/local/lib/python3.8/site-packages/django/views/generic/list.py", line 174, in get
    context = self.get_context_data()
  File "/web_django/women/views.py", line 22, in get_context_data
    context = super().get_context_data(**kwargs)
  File "/usr/local/lib/python3.8/site-packages/django/views/generic/list.py", line 128, in get_context_data
    paginator, page, queryset, is_paginated = self.paginate_queryset(
  File "/usr/local/lib/python3.8/site-packages/django/views/generic/list.py", line 73, in paginate_queryset
    page = paginator.page(page_number)
  File "/usr/local/lib/python3.8/site-packages/django/core/paginator.py", line 75, in page
    number = self.validate_number(number)
  File "/usr/local/lib/python3.8/site-packages/django/core/paginator.py", line 53, in validate_number
    if number > self.num_pages:
  File "/usr/local/lib/python3.8/site-packages/django/utils/functional.py", line 49, in __get__
    res = instance.__dict__[self.name] = self.func(instance)
  File "/usr/local/lib/python3.8/site-packages/django/core/paginator.py", line 102, in num_pages
    if self.count == 0 and not self.allow_empty_first_page:
  File "/usr/local/lib/python3.8/site-packages/django/utils/functional.py", line 49, in __get__
    res = instance.__dict__[self.name] = self.func(instance)
  File "/usr/local/lib/python3.8/site-packages/django/core/paginator.py", line 96, in count
    return c()
  File "/usr/local/lib/python3.8/site-packages/django/db/models/query.py", line 470, in count
    return self.query.get_count(using=self.db)
  File "/usr/local/lib/python3.8/site-packages/django/db/models/sql/query.py", line 552, in get_count
    number = obj.get_aggregation(using, ["__count"])["__count"]
  File "/usr/local/lib/python3.8/site-packages/django/db/models/sql/query.py", line 537, in get_aggregation
    result = compiler.execute_sql(SINGLE)
  File "/usr/local/lib/python3.8/site-packages/django/db/models/sql/compiler.py", line 1361, in execute_sql
    cursor.execute(sql, params)
  File "/usr/local/lib/python3.8/site-packages/django/db/backends/utils.py", line 103, in execute
    return super().execute(sql, params)
  File "/usr/local/lib/python3.8/site-packages/django/db/backends/utils.py", line 67, in execute
    return self._execute_with_wrappers(
  File "/usr/local/lib/python3.8/site-packages/django/db/backends/utils.py", line 80, in _execute_with_wrappers
    return executor(sql, params, many, context)
  File "/usr/local/lib/python3.8/site-packages/django/db/backends/utils.py", line 89, in _execute
    return self.cursor.execute(sql, params)
  File "/usr/local/lib/python3.8/site-packages/django/db/utils.py", line 91, in __exit__
    raise dj_exc_value.with_traceback(traceback) from exc_value
  File "/usr/local/lib/python3.8/site-packages/django/db/backends/utils.py", line 89, in _execute
    return self.cursor.execute(sql, params)
django.db.utils.ProgrammingError: relation "women_women" does not exist
LINE 1: SELECT COUNT(*) AS "__count" FROM "women_women" WHERE "women...
                                          ^

2022-05-19 20:19:14 [ERROR   ] (log.log_response) Internal Server Error: /
Traceback (most recent call last):
  File "/usr/local/lib/python3.8/site-packages/django/db/backends/utils.py", line 89, in _execute
    return self.cursor.execute(sql, params)
psycopg2.errors.UndefinedTable: relation "women_women" does not exist
LINE 1: SELECT COUNT(*) AS "__count" FROM "women_women" WHERE "women...
                                          ^


The above exception was the direct cause of the following exception:

Traceback (most recent call last):
  File "/usr/local/lib/python3.8/site-packages/django/core/handlers/exception.py", line 55, in inner
    response = get_response(request)
  File "/usr/local/lib/python3.8/site-packages/django/core/handlers/base.py", line 197, in _get_response
    response = wrapped_callback(request, *callback_args, **callback_kwargs)
  File "/usr/local/lib/python3.8/site-packages/django/views/generic/base.py", line 84, in view
    return self.dispatch(request, *args, **kwargs)
  File "/usr/local/lib/python3.8/site-packages/django/views/generic/base.py", line 119, in dispatch
    return handler(request, *args, **kwargs)
  File "/usr/local/lib/python3.8/site-packages/django/views/generic/list.py", line 174, in get
    context = self.get_context_data()
  File "/web_django/women/views.py", line 22, in get_context_data
    context = super().get_context_data(**kwargs)
  File "/usr/local/lib/python3.8/site-packages/django/views/generic/list.py", line 128, in get_context_data
    paginator, page, queryset, is_paginated = self.paginate_queryset(
  File "/usr/local/lib/python3.8/site-packages/django/views/generic/list.py", line 73, in paginate_queryset
    page = paginator.page(page_number)
  File "/usr/local/lib/python3.8/site-packages/django/core/paginator.py", line 75, in page
    number = self.validate_number(number)
  File "/usr/local/lib/python3.8/site-packages/django/core/paginator.py", line 53, in validate_number
    if number > self.num_pages:
  File "/usr/local/lib/python3.8/site-packages/django/utils/functional.py", line 49, in __get__
    res = instance.__dict__[self.name] = self.func(instance)
  File "/usr/local/lib/python3.8/site-packages/django/core/paginator.py", line 102, in num_pages
    if self.count == 0 and not self.allow_empty_first_page:
  File "/usr/local/lib/python3.8/site-packages/django/utils/functional.py", line 49, in __get__
    res = instance.__dict__[self.name] = self.func(instance)
  File "/usr/local/lib/python3.8/site-packages/django/core/paginator.py", line 96, in count
    return c()
  File "/usr/local/lib/python3.8/site-packages/django/db/models/query.py", line 470, in count
    return self.query.get_count(using=self.db)
  File "/usr/local/lib/python3.8/site-packages/django/db/models/sql/query.py", line 552, in get_count
    number = obj.get_aggregation(using, ["__count"])["__count"]
  File "/usr/local/lib/python3.8/site-packages/django/db/models/sql/query.py", line 537, in get_aggregation
    result = compiler.execute_sql(SINGLE)
  File "/usr/local/lib/python3.8/site-packages/django/db/models/sql/compiler.py", line 1361, in execute_sql
    cursor.execute(sql, params)
  File "/usr/local/lib/python3.8/site-packages/django/db/backends/utils.py", line 103, in execute
    return super().execute(sql, params)
  File "/usr/local/lib/python3.8/site-packages/django/db/backends/utils.py", line 67, in execute
    return self._execute_with_wrappers(
  File "/usr/local/lib/python3.8/site-packages/django/db/backends/utils.py", line 80, in _execute_with_wrappers
    return executor(sql, params, many, context)
  File "/usr/local/lib/python3.8/site-packages/django/db/backends/utils.py", line 89, in _execute
    return self.cursor.execute(sql, params)
  File "/usr/local/lib/python3.8/site-packages/django/db/utils.py", line 91, in __exit__
    raise dj_exc_value.with_traceback(traceback) from exc_value
  File "/usr/local/lib/python3.8/site-packages/django/db/backends/utils.py", line 89, in _execute
    return self.cursor.execute(sql, params)
django.db.utils.ProgrammingError: relation "women_women" does not exist
LINE 1: SELECT COUNT(*) AS "__count" FROM "women_women" WHERE "women...
                                          ^

2022-05-19 20:19:14 [ERROR   ] (basehttp.log_message) "GET / HTTP/1.1" 500 156997
2022-05-19 20:19:14 [ERROR   ] (basehttp.log_message) "GET / HTTP/1.1" 500 156997
